Workbook
Name BenchTicker: Params!$B$5
Name DataEnd: Params!$B$10
Name DataStart: Params!$B$9
Name FxCurrency: Params!$B$7
Name IndexTicker: Params!$B$4
Name MembersStart: Params!$B$8
Name RfTicker: Params!$B$6
Name SwitchPB: Params!$B$15
Name SwitchROE: Params!$B$16
Name SwitchTR: Params!$B$14
Name SwitchUniverse: Params!$B$13

Sheet README
A1: STOXX Europe 600 extraction for the SFC backtest (ls_backtest)
A2: Downloads from Bloomberg the monthly data the model needs (index members, total return index, price-to-book, ROE, sectors, benchmark, risk-free rate) for every stock that was in the STOXX Europe 600 between 2005 and 2025, delisted stocks included.
A3: Before you start
A4: 1. Use a Bloomberg terminal with the Excel add-in (Bloomberg tab in the ribbon) and Microsoft 365: the Universe sheet uses dynamic array formulas (SORT, UNIQUE, FILTER).
A5: 2. First save a copy under the name SXXP_extraction.xlsx (File > Save As), outside the repository's bloomberg/ folder: that template must stay empty because it is on GitHub, while the refreshed copy holds licensed Bloomberg data.
A6: 3. Bloomberg caps the data a user can download per day and per month. The full extraction is large (about 1,500 stocks x 288 months x 3 fields): run one step per session and stop if cells show a limit message (e.g. #N/A Limit).
A7: Steps (switches and checks are in the Params sheet)
A8: Step 1 - Members (automatic on opening): index members at each of the 252 month-ends (BDS INDX_MWEIGHT_HIST). Wait until Params shows 252 months loaded.
A9: Step 2 - Universe: set the Universe switch to ON. Names and GICS sectors of every stock ever in the index (BDP).
A10: Step 3 - TR: set the TR switch to ON and wait until 'TR blocks with data' is close to 'Stocks in the universe' (delisted stocks may lack data). Save.
A11: Step 4 - PB: same with the PB switch. Save.
A12: Step 5 - ROE: same with the ROE switch. Save.
... A26: - More than 2,000 stocks (see Params): copy the last two columns of TR, PB and ROE to the right and increase the Universe row number in their row-1 formulas.

Sheet Params
A1: Parameters
A2: Edit the blue cells if needed; switch the yellow cells to ON one step at a time (README sheet).
A4: Index (membership) | B4: SXXP Index | C4: STOXX Europe 600: its historical members define the universe
A5: Benchmark | B5: SXXGR Index | C5: STOXX Europe 600 gross return in EUR (like the stocks' gross total returns); net return: SXXR Index
A6: Risk-free rate | B6: EUR001M Index | C6: 1-month Euribor, annualized, in %
A7: Currency | B7: EUR | C7: Total return indices are converted into this currency
A8: First membership month-end | B8: 38383 | C8: 252 month-ends from this date (Members sheet)
A9: Data start | B9: 37287 | C9: 3 years earlier: momentum and volatility need past prices
A10: Data end | B10: 46022 | C10: Last month-end
A12: Download switches (OFF / ON)
A13: Step 2 - Universe: names and sectors | B13: OFF | C13: Turn ON only once Members is complete (252 months loaded)
A14: Step 3 - TR: total return index | B14: OFF
A15: Step 4 - PB: price to book | B15: OFF
A16: Step 5 - ROE: return on equity | B16: OFF
A18: Checks
A19: Months loaded (expected 252) | B19: =COUNTIF(Members!$B$2:$B$153721,">=590") -> 0
A20: Stocks in the universe | B20: =COUNTIF(Universe!$B$2:$B$2001,"?*") -> 0 | C20: =IF(B20>=2000,"More stocks than slots: see README, Troubleshooting","OK: "&(2000-B20)&" free slots")
A21: TR blocks with data | B21: =COUNTIF(TR!$A$2:$EWV$2,">0") -> 0
A22: PB blocks with data | B22: =COUNTIF(PB!$A$2:$EWV$2,">0") -> 0
A23: ROE blocks with data | B23: =COUNTIF(ROE!$A$2:$EWV$2,">0") -> 0
A24: Benchmark months loaded | B24: =Benchmark!A2 -> 0
A25: Risk-free months loaded | B25: =Benchmark!C2 -> 0

Sheet Members
A1: Month-end | B1: Member | C1: Weight (%)
A2: =EOMONTH(MembersStart,0) | B2: =COUNTA(B3:B611) -> 0
B3: =BDS(IndexTicker,"INDX_MWEIGHT_HIST","END_DATE_OVERRIDE="&(YEAR($A2)*10000+MONTH($A2)*100+DAY($A2)))
A612: =EOMONTH(A2,1) | B612: =COUNTA(B613:B1221) -> 0
B613: =BDS(IndexTicker,"INDX_MWEIGHT_HIST","END_DATE_OVERRIDE="&(YEAR($A612)*10000+MONTH($A612)*100+DAY($A612)))
A1222: =EOMONTH(A612,1) | B1222: =COUNTA(B1223:B1831) -> 0
B1223: =BDS(IndexTicker,"INDX_MWEIGHT_HIST","END_DATE_OVERRIDE="&(YEAR($A1222)*10000+MONTH($A1222)*100+DAY($A1222)))
A1832: =EOMONTH(A1222,1) | B1832: =COUNTA(B1833:B2441) -> 0
B1833: =BDS(IndexTicker,"INDX_MWEIGHT_HIST","END_DATE_OVERRIDE="&(YEAR($A1832)*10000+MONTH($A1832)*100+DAY($A1832)))
A2442: =EOMONTH(A1832,1) | B2442: =COUNTA(B2443:B3051) -> 0
B2443: =BDS(IndexTicker,"INDX_MWEIGHT_HIST","END_DATE_OVERRIDE="&(YEAR($A2442)*10000+MONTH($A2442)*100+DAY($A2442)))
A3052: =EOMONTH(A2442,1) | B3052: =COUNTA(B3053:B3661) -> 0
B3053: =BDS(IndexTicker,"INDX_MWEIGHT_HIST","END_DATE_OVERRIDE="&(YEAR($A3052)*10000+MONTH($A3052)*100+DAY($A3052)))
A3662: =EOMONTH(A3052,1) | B3662: =COUNTA(B3663:B4271) -> 0
B3663: =BDS(IndexTicker,"INDX_MWEIGHT_HIST","END_DATE_OVERRIDE="&(YEAR($A3662)*10000+MONTH($A3662)*100+DAY($A3662)))
A4272: =EOMONTH(A3662,1) | B4272: =COUNTA(B4273:B4881) -> 0
B4273: =BDS(IndexTicker,"INDX_MWEIGHT_HIST","END_DATE_OVERRIDE="&(YEAR($A4272)*10000+MONTH($A4272)*100+DAY($A4272)))
A4882: =EOMONTH(A4272,1) | B4882: =COUNTA(B4883:B5491) -> 0
B4883: =BDS(IndexTicker,"INDX_MWEIGHT_HIST","END_DATE_OVERRIDE="&(YEAR($A4882)*10000+MONTH($A4882)*100+DAY($A4882)))
A5492: =EOMONTH(A4882,1) | B5492: =COUNTA(B5493:B6101) -> 0
B5493: =BDS(IndexTicker,"INDX_MWEIGHT_HIST","END_DATE_OVERRIDE="&(YEAR($A5492)*10000+MONTH($A5492)*100+DAY($A5492)))
A6102: =EOMONTH(A5492,1) | B6102: =COUNTA(B6103:B6711) -> 0
B6103: =BDS(IndexTicker,"INDX_MWEIGHT_HIST","END_DATE_OVERRIDE="&(YEAR($A6102)*10000+MONTH($A6102)*100+DAY($A6102)))
A6712: =EOMONTH(A6102,1) | B6712: =COUNTA(B6713:B7321) -> 0
B6713: =BDS(IndexTicker,"INDX_MWEIGHT_HIST","END_DATE_OVERRIDE="&(YEAR($A6712)*10000+MONTH($A6712)*100+DAY($A6712)))
A7322: =EOMONTH(A6712,1) | B7322: =COUNTA(B7323:B7931) -> 0
B7323: =BDS(IndexTicker,"INDX_MWEIGHT_HIST","END_DATE_OVERRIDE="&(YEAR($A7322)*10000+MONTH($A7322)*100+DAY($A7322)))
A7932: =EOMONTH(A7322,1) | B7932: =COUNTA(B7933:B8541) -> 0
B7933: =BDS(IndexTicker,"INDX_MWEIGHT_HIST","END_DATE_OVERRIDE="&(YEAR($A7932)*10000+MONTH($A7932)*100+DAY($A7932)))
A8542: =EOMONTH(A7932,1) | B8542: =COUNTA(B8543:B9151) -> 0
B8543: =BDS(IndexTicker,"INDX_MWEIGHT_HIST","END_DATE_OVERRIDE="&(YEAR($A8542)*10000+MONTH($A8542)*100+DAY($A8542)))
A9152: =EOMONTH(A8542,1) | B9152: =COUNTA(B9153:B9761) -> 0
B9153: =BDS(IndexTicker,"INDX_MWEIGHT_HIST","END_DATE_OVERRIDE="&(YEAR($A9152)*10000+MONTH($A9152)*100+DAY($A9152)))
A9762: =EOMONTH(A9152,1) | B9762: =COUNTA(B9763:B10371) -> 0
B9763: =BDS(IndexTicker,"INDX_MWEIGHT_HIST","END_DATE_OVERRIDE="&(YEAR($A9762)*10000+MONTH($A9762)*100+DAY($A9762)))
A10372: =EOMONTH(A9762,1) | B10372: =COUNTA(B10373:B10981) -> 0
B10373: =BDS(IndexTicker,"INDX_MWEIGHT_HIST","END_DATE_OVERRIDE="&(YEAR($A10372)*10000+MONTH($A10372)*100+DAY($A10372)))
A10982: =EOMONTH(A10372,1) | B10982: =COUNTA(B10983:B11591) -> 0
B10983: =BDS(IndexTicker,"INDX_MWEIGHT_HIST","END_DATE_OVERRIDE="&(YEAR($A10982)*10000+MONTH($A10982)*100+DAY($A10982)))
A11592: =EOMONTH(A10982,1) | B11592: =COUNTA(B11593:B12201) -> 0
...

Sheet Universe
A1: Member | B1: Ticker | C1: Name | D1: GICS sector
A2: {=_xlfn._xlws.SORT(_xlfn.UNIQUE(_xlfn._xlws.FILTER(Members!$B$3:$B$153721,ISTEXT(Members!$B$3:$B$153721)*(IFERROR(LEFT(Members!$B$3:$B$153721,1),"#")<>"#")*(Members!$B$3:$B$153721<>"Index Member"),"")))} | B2: =IF(TRIM(A2&"")="","",IF(RIGHT(TRIM(A2),7)=" Equity",TRIM(A2),TRIM(A2)&" Equity")) | C2: =IF(OR(SwitchUniverse<>"ON",$B2=""),"",BDP($B2,"NAME")) | D2: =IF(OR(SwitchUniverse<>"ON",$B2=""),"",BDP($B2,"GICS_SECTOR_NAME"))
B3: =IF(TRIM(A3&"")="","",IF(RIGHT(TRIM(A3),7)=" Equity",TRIM(A3),TRIM(A3)&" Equity")) | C3: =IF(OR(SwitchUniverse<>"ON",$B3=""),"",BDP($B3,"NAME")) | D3: =IF(OR(SwitchUniverse<>"ON",$B3=""),"",BDP($B3,"GICS_SECTOR_NAME"))
B4: =IF(TRIM(A4&"")="","",IF(RIGHT(TRIM(A4),7)=" Equity",TRIM(A4),TRIM(A4)&" Equity")) | C4: =IF(OR(SwitchUniverse<>"ON",$B4=""),"",BDP($B4,"NAME")) | D4: =IF(OR(SwitchUniverse<>"ON",$B4=""),"",BDP($B4,"GICS_SECTOR_NAME"))
B5: =IF(TRIM(A5&"")="","",IF(RIGHT(TRIM(A5),7)=" Equity",TRIM(A5),TRIM(A5)&" Equity")) | C5: =IF(OR(SwitchUniverse<>"ON",$B5=""),"",BDP($B5,"NAME")) | D5: =IF(OR(SwitchUniverse<>"ON",$B5=""),"",BDP($B5,"GICS_SECTOR_NAME"))
B6: =IF(TRIM(A6&"")="","",IF(RIGHT(TRIM(A6),7)=" Equity",TRIM(A6),TRIM(A6)&" Equity")) | C6: =IF(OR(SwitchUniverse<>"ON",$B6=""),"",BDP($B6,"NAME")) | D6: =IF(OR(SwitchUniverse<>"ON",$B6=""),"",BDP($B6,"GICS_SECTOR_NAME"))
B7: =IF(TRIM(A7&"")="","",IF(RIGHT(TRIM(A7),7)=" Equity",TRIM(A7),TRIM(A7)&" Equity")) | C7: =IF(OR(SwitchUniverse<>"ON",$B7=""),"",BDP($B7,"NAME")) | D7: =IF(OR(SwitchUniverse<>"ON",$B7=""),"",BDP($B7,"GICS_SECTOR_NAME"))
B8: =IF(TRIM(A8&"")="","",IF(RIGHT(TRIM(A8),7)=" Equity",TRIM(A8),TRIM(A8)&" Equity")) | C8: =IF(OR(SwitchUniverse<>"ON",$B8=""),"",BDP($B8,"NAME")) | D8: =IF(OR(SwitchUniverse<>"ON",$B8=""),"",BDP($B8,"GICS_SECTOR_NAME"))
B9: =IF(TRIM(A9&"")="","",IF(RIGHT(TRIM(A9),7)=" Equity",TRIM(A9),TRIM(A9)&" Equity")) | C9: =IF(OR(SwitchUniverse<>"ON",$B9=""),"",BDP($B9,"NAME")) | D9: =IF(OR(SwitchUniverse<>"ON",$B9=""),"",BDP($B9,"GICS_SECTOR_NAME"))
B10: =IF(TRIM(A10&"")="","",IF(RIGHT(TRIM(A10),7)=" Equity",TRIM(A10),TRIM(A10)&" Equity")) | C10: =IF(OR(SwitchUniverse<>"ON",$B10=""),"",BDP($B10,"NAME")) | D10: =IF(OR(SwitchUniverse<>"ON",$B10=""),"",BDP($B10,"GICS_SECTOR_NAME"))
B11: =IF(TRIM(A11&"")="","",IF(RIGHT(TRIM(A11),7)=" Equity",TRIM(A11),TRIM(A11)&" Equity")) | C11: =IF(OR(SwitchUniverse<>"ON",$B11=""),"",BDP($B11,"NAME")) | D11: =IF(OR(SwitchUniverse<>"ON",$B11=""),"",BDP($B11,"GICS_SECTOR_NAME"))
B12: =IF(TRIM(A12&"")="","",IF(RIGHT(TRIM(A12),7)=" Equity",TRIM(A12),TRIM(A12)&" Equity")) | C12: =IF(OR(SwitchUniverse<>"ON",$B12=""),"",BDP($B12,"NAME")) | D12: =IF(OR(SwitchUniverse<>"ON",$B12=""),"",BDP($B12,"GICS_SECTOR_NAME"))
B13: =IF(TRIM(A13&"")="","",IF(RIGHT(TRIM(A13),7)=" Equity",TRIM(A13),TRIM(A13)&" Equity")) | C13: =IF(OR(SwitchUniverse<>"ON",$B13=""),"",BDP($B13,"NAME")) | D13: =IF(OR(SwitchUniverse<>"ON",$B13=""),"",BDP($B13,"GICS_SECTOR_NAME"))
B14: =IF(TRIM(A14&"")="","",IF(RIGHT(TRIM(A14),7)=" Equity",TRIM(A14),TRIM(A14)&" Equity")) | C14: =IF(OR(SwitchUniverse<>"ON",$B14=""),"",BDP($B14,"NAME")) | D14: =IF(OR(SwitchUniverse<>"ON",$B14=""),"",BDP($B14,"GICS_SECTOR_NAME"))
... B2001: =IF(TRIM(A2001&"")="","",IF(RIGHT(TRIM(A2001),7)=" Equity",TRIM(A2001),TRIM(A2001)&" Equity")) | C2001: =IF(OR(SwitchUniverse<>"ON",$B2001=""),"",BDP($B2001,"NAME")) | D2001: =IF(OR(SwitchUniverse<>"ON",$B2001=""),"",BDP($B2001,"GICS_SECTOR_NAME"))

Sheet TR
